Workbook

Sheet convert_to_emaxis_slim
A1: 日付 | B1: 国内株式 | C1: 先進国株式 | D1: 全世界株式 | E1: 米国株式 | F1: バランス
A2: 42739 | B2: =B$494/morningstar!B$494*morningstar!B2 -> 8220.8125 | C2: =C$494/morningstar!C$494*morningstar!C2 -> 0 | D2: =D$494/morningstar!D$494*morningstar!D2 -> 8964.8673 | E2: =E$494/morningstar!E$494*morningstar!E2 -> 0 | F2: =F$494/morningstar!F$494*morningstar!F2 -> 0
A3: 42740 | B3: =B$494/morningstar!B$494*morningstar!B3 -> 8189.9319 | C3: =C$494/morningstar!C$494*morningstar!C3 -> 0 | D3: =D$494/morningstar!D$494*morningstar!D3 -> 8931.5525 | E3: =E$494/morningstar!E$494*morningstar!E3 -> 0 | F3: =F$494/morningstar!F$494*morningstar!F3 -> 0
A4: 42741 | B4: =B$494/morningstar!B$494*morningstar!B4 -> 8161.7533 | C4: =C$494/morningstar!C$494*morningstar!C4 -> 0 | D4: =D$494/morningstar!D$494*morningstar!D4 -> 8893.4784 | E4: =E$494/morningstar!E$494*morningstar!E4 -> 0 | F4: =F$494/morningstar!F$494*morningstar!F4 -> 0
A5: 42745 | B5: =B$494/morningstar!B$494*morningstar!B5 -> 8097.6759 | C5: =C$494/morningstar!C$494*morningstar!C5 -> 0 | D5: =D$494/morningstar!D$494*morningstar!D5 -> 8898.2376 | E5: =E$494/morningstar!E$494*morningstar!E5 -> 0 | F5: =F$494/morningstar!F$494*morningstar!F5 -> 0
A6: 42746 | B6: =B$494/morningstar!B$494*morningstar!B6 -> 8123.9245 | C6: =C$494/morningstar!C$494*morningstar!C6 -> 0 | D6: =D$494/morningstar!D$494*morningstar!D6 -> 8905.7731 | E6: =E$494/morningstar!E$494*morningstar!E6 -> 0 | F6: =F$494/morningstar!F$494*morningstar!F6 -> 0
A7: 42747 | B7: =B$494/morningstar!B$494*morningstar!B7 -> 8027.0365 | C7: =C$494/morningstar!C$494*morningstar!C7 -> 0 | D7: =D$494/morningstar!D$494*morningstar!D7 -> 8884.753 | E7: =E$494/morningstar!E$494*morningstar!E7 -> 0 | F7: =F$494/morningstar!F$494*morningstar!F7 -> 0
A8: 42748 | B8: =B$494/morningstar!B$494*morningstar!B8 -> 8091.1138 | C8: =C$494/morningstar!C$494*morningstar!C8 -> 0 | D8: =D$494/morningstar!D$494*morningstar!D8 -> 8858.1805 | E8: =E$494/morningstar!E$494*morningstar!E8 -> 0 | F8: =F$494/morningstar!F$494*morningstar!F8 -> 0
A9: 42751 | B9: =B$494/morningstar!B$494*morningstar!B9 -> 8010.0521 | C9: =C$494/morningstar!C$494*morningstar!C9 -> 0 | D9: =D$494/morningstar!D$494*morningstar!D9 -> 8831.6079 | E9: =E$494/morningstar!E$494*morningstar!E9 -> 0 | F9: =F$494/morningstar!F$494*morningstar!F9 -> 0
A10: 42752 | B10: =B$494/morningstar!B$494*morningstar!B10 -> 7891.1617 | C10: =C$494/morningstar!C$494*morningstar!C10 -> 0 | D10: =D$494/morningstar!D$494*morningstar!D10 -> 8792.7406 | E10: =E$494/morningstar!E$494*morningstar!E10 -> 0 | F10: =F$494/morningstar!F$494*morningstar!F10 -> 0
A11: 42753 | B11: =B$494/morningstar!B$494*morningstar!B11 -> 7925.5164 | C11: =C$494/morningstar!C$494*morningstar!C11 -> 0 | D11: =D$494/morningstar!D$494*morningstar!D11 -> 8700.3316 | E11: =E$494/morningstar!E$494*morningstar!E11 -> 0 | F11: =F$494/morningstar!F$494*morningstar!F11 -> 0
A12: 42754 | B12: =B$494/morningstar!B$494*morningstar!B12 -> 8000.7879 | C12: =C$494/morningstar!C$494*morningstar!C12 -> 0 | D12: =D$494/morningstar!D$494*morningstar!D12 -> 8852.2314 | E12: =E$494/morningstar!E$494*morningstar!E12 -> 0 | F12: =F$494/morningstar!F$494*morningstar!F12 -> 0
A13: 42755 | B13: =B$494/morningstar!B$494*morningstar!B13 -> 8028.1945 | C13: =C$494/morningstar!C$494*morningstar!C13 -> 0 | D13: =D$494/morningstar!D$494*morningstar!D13 -> 8857.7839 | E13: =E$494/morningstar!E$494*morningstar!E13 -> 0 | F13: =F$494/morningstar!F$494*morningstar!F13 -> 0
... A493: 43462 | B493: =B$494/morningstar!B$494*morningstar!B493 -> 8683.2501 | C493: =C$494/morningstar!C$494*morningstar!C493 -> 10346 | D493: =D$494/morningstar!D$494*morningstar!D493 -> 9269.8568 | E493: =E$494/morningstar!E$494*morningstar!E493 -> 9233.4548 | F493: =F$494/morningstar!F$494*morningstar!F493 -> 10058
A494: 43469 | B494: 8486 | C494: 9957 | D494: 8926 | E494: 8809 | F494: 9831
A495: 43472 | B495: 8694 | C495: 10358 | D495: 9261 | E495: 9184 | F495: 10016
A496: 43473 | B496: 8765 | C496: 10452 | D496: 9346 | E496: 9272 | F496: 10074
A497: 43474 | B497: 8862 | C497: 10538 | D497: 9414 | E497: 9354 | F497: 10120
A498: 43475 | B498: 8747 | C498: 10570 | D498: 9448 | E498: 9350 | F498: 10135
A499: 43476 | B499: 8832 | C499: 10632 | D499: 9504 | E499: 9416 | F499: 10189
A500: 43480 | B500: 8917 | C500: 10567 | D500: 9456 | E500: 9360 | F500: 10170
A501: 43481 | B501: 8868 | C501: 10656 | D501: 9531 | E501: 9463 | F501: 10209
A502: 43482 | B502: 8851 | C502: 10733 | D502: 9600 | E502: 9531 | F502: 10274
A503: 43483 | B503: 8965 | C503: 10836 | D503: 9685 | E503: 9641 | F503: 10322
A504: 43486 | B504: 8989 | C504: 11002 | D504: 9820 | E504: 9794 | F504: 10373
A505: 43487 | B505: 8946 | C505: 11001 | D505: 9816 | E505: 9796 | F505: 10361
... A1364: 44775 | B1364: 12737 | C1364: 19605 | D1364: 16479 | E1364: 18917 | F1364: 13482

Sheet morningstar
A1: 日付 | B1: 国内株式 | C1: 先進国株式 | D1: 全世界株式 | E1: 米国株式 | F1: バランス
A2: 42739 | B2: 21297 | D2: 22604
A3: 42740 | B3: 21217 | D3: 22520
A4: 42741 | B4: 21144 | D4: 22424
A5: 42745 | B5: 20978 | D5: 22436
A6: 42746 | B6: 21046 | D6: 22455
A7: 42747 | B7: 20795 | D7: 22402
A8: 42748 | B8: 20961 | D8: 22335
A9: 42751 | B9: 20751 | D9: 22268
A10: 42752 | B10: 20443 | D10: 22170
A11: 42753 | B11: 20532 | D11: 21937
A12: 42754 | B12: 20727 | D12: 22320
A13: 42755 | B13: 20798 | D13: 22334
... A38: 42790 | B38: 20963 | D38: 22820
A39: 42793 | B39: 20773 | C39: 9914 | D39: 22603
A40: 42794 | B40: 20784 | C40: 9954 | D40: 22681
A41: 42795 | B41: 21081 | C41: 9985 | D41: 22746
A42: 42796 | B42: 21270 | C42: 10184 | D42: 23178
A43: 42797 | B43: 21163 | C43: 10161 | D43: 23122
A44: 42800 | B44: 21065 | C44: 10140 | D44: 23065
A45: 42801 | B45: 21027 | C45: 10119 | D45: 23032
A46: 42802 | B46: 20929 | C46: 10089 | D46: 22976
A47: 42803 | B47: 20999 | C47: 10122 | D47: 23047
A48: 42804 | B48: 21309 | C48: 10191 | D48: 23171
A49: 42807 | B49: 21342 | C49: 10206 | D49: 23205
A50: 42808 | B50: 21314 | C50: 10222 | D50: 23270
... A85: 42863 | B85: 21776 | C85: 10352 | D85: 23588
A86: 42864 | B86: 21719 | C86: 10390 | D86: 23691 | F86: 10019
A87: 42865 | B87: 21781 | C87: 10435 | D87: 23815 | F87: 10051
A88: 42866 | B88: 21851 | C88: 10484 | D88: 23941 | F88: 10090
A89: 42867 | B89: 21766 | C89: 10431 | D89: 23842 | F89: 10067
A90: 42870 | B90: 21752 | C90: 10397 | D90: 23763 | F90: 10051
A91: 42871 | B91: 21805 | C91: 10487 | D91: 23981 | F91: 10101
A92: 42872 | B92: 21690 | C92: 10404 | D92: 23794 | F92: 10049
A93: 42873 | B93: 21407 | C93: 10116 | D93: 23148 | F93: 9931
A94: 42874 | B94: 21446 | C94: 10142 | D94: 23152 | F94: 9899
A95: 42877 | B95: 21541 | C95: 10242 | D95: 23390 | F95: 9961
A96: 42878 | B96: 21471 | C96: 10260 | D96: 23435 | F96: 9964
A97: 42879 | B97: 21612 | C97: 10326 | D97: 23582 | F97: 10002
... A165: 42977 | B165: 21375 | C165: 10385 | D165: 23874 | F165: 10172
...
